Workbook

Sheet S2_Summary
A1: Drug | B1: Degree (all edges) | C1: Tier 1 edges | D1: Tier 2 edges
A2: Ivermectin | B2: =COUNTIF(S1_Edges!$A$2:$A$55,A2) -> 16 | C2: =COUNTIFS(S1_Edges!$A$2:$A$55,A2,S1_Edges!$I$2:$I$55,"Tier 1") -> 9 | D2: =COUNTIFS(S1_Edges!$A$2:$A$55,A2,S1_Edges!$I$2:$I$55,"Tier 2") -> 7
A3: Dronedarone | B3: =COUNTIF(S1_Edges!$A$2:$A$55,A3) -> 18 | C3: =COUNTIFS(S1_Edges!$A$2:$A$55,A3,S1_Edges!$I$2:$I$55,"Tier 1") -> 11 | D3: =COUNTIFS(S1_Edges!$A$2:$A$55,A3,S1_Edges!$I$2:$I$55,"Tier 2") -> 7
A4: Fenbendazole | B4: =COUNTIF(S1_Edges!$A$2:$A$55,A4) -> 10 | C4: =COUNTIFS(S1_Edges!$A$2:$A$55,A4,S1_Edges!$I$2:$I$55,"Tier 1") -> 4 | D4: =COUNTIFS(S1_Edges!$A$2:$A$55,A4,S1_Edges!$I$2:$I$55,"Tier 2") -> 6
A5: Methylene Blue | B5: =COUNTIF(S1_Edges!$A$2:$A$55,A5) -> 10 | C5: =COUNTIFS(S1_Edges!$A$2:$A$55,A5,S1_Edges!$I$2:$I$55,"Tier 1") -> 10 | D5: =COUNTIFS(S1_Edges!$A$2:$A$55,A5,S1_Edges!$I$2:$I$55,"Tier 2") -> 0
A6: Total edges | B6: =SUM(B2:B5) -> 54 | C6: =SUM(C2:C5) -> 34 | D6: =SUM(D2:D5) -> 20
A8: Network metric | B8: Full network (all edges) | C8: Strict network (Tier 1 only)
A9: Drug nodes | B9: 4 | C9: 4
A10: Unique target nodes | B10: =SUMPRODUCT(1/COUNTIF(S1_Edges!$B$2:$B$55,S1_Edges!$B$2:$B$55)) -> 52 | C10: =SUMPRODUCT((S1_Edges!$I$2:$I$55="Tier 1")/(COUNTIFS(S1_Edges!$B$2:$B$55,S1_Edges!$B$2:$B$55,S1_Edges!$I$2:$I$55,"Tier 1")+(S1_Edges!$I$2:$I$55<>"Tier 1"))) -> 33
A11: Total nodes | B11: =B9+B10 -> 56 | C11: =C9+C10 -> 37
A12: Edges | B12: =B6 -> 54 | C12: =C6 -> 34
A13: Targets shared by ≥2 drugs | B13: =SUMPRODUCT((COUNTIF(S1_Edges!$B$2:$B$55,S1_Edges!$B$2:$B$55)>1)/COUNTIF(S1_Edges!$B$2:$B$55,S1_Edges!$B$2:$B$55)) -> 2 | C13: =SUMPRODUCT((S1_Edges!$I$2:$I$55="Tier 1")*(COUNTIFS(S1_Edges!$B$2:$B$55,S1_Edges!$B$2:$B$55,S1_Edges!$I$2:$I$55,"Tier 1")>1)/(COUNTIFS(S1_Edges!$B$2:$B$55,S1_Edges!$B$2:$B$55,S1_Edges!$I$2:$I$55,"Tier 1")+(S1_Edges!$I$2:$I$55<>"Tier 1"))) -> 1
A14: Shared targets as % of targets | B14: =B13/B10 -> 0.038461538 | C14: =C13/C10 -> 0.03030303
A16: Shared targets in the full network: ABCB1 (ivermectin, dronedarone) and CYP2D6 (dronedarone, methylene blue). In the strict network only CYP2D6 remains shared; the dronedarone–ABCB1 edge is Tier 2 (probability 0.282).
A18: Note: the sheet S1_Edges in this file is a copy of Table S1 (the input for the formulas above). Edit Table S1 and paste it here to update the summary.

Sheet S1_Edges
A1: Drug | B1: Gene | C1: Protein name | D1: UniProt accession | E1: SwissTargetPrediction probability | F1: STITCH combined score | G1: ChEMBL confidence (as recorded) | H1: Source(s) | I1: Tier | J1: Retention note
A2: Ivermectin | B2: ABCB1 | C2: ATP-dependent translocase ABCB1 | D2: P08183 | F2: 0.97 | H2: STITCH | I2: Tier 1 | J2: Meets threshold
A3: Ivermectin | B3: ABCG2 | C3: ATP-binding cassette sub-family G member 2 | D3: Q9UNQ0 | F3: 0.768 | H3: STITCH | I3: Tier 1 | J3: Meets threshold
A4: Ivermectin | B4: ATP2A1 | C4: Sarcoplasmic/endoplasmic reticulum calcium ATPase 1 | D4: O14983 | E4: 0.353 | H4: SwissTargetPrediction | I4: Tier 1 | J4: Meets threshold
A5: Ivermectin | B5: GABRB3 | C5: Gamma-aminobutyric acid receptor subunit beta-3 | D5: P28472 | F5: 0.842 | H5: STITCH | I5: Tier 1 | J5: Meets threshold
A6: Ivermectin | B6: GLRA3 | C6: Glycine receptor subunit alpha-3 | D6: O75311 | F6: 0.842 | H6: STITCH | I6: Tier 1 | J6: Meets threshold
A7: Ivermectin | B7: NNMT | C7: Nicotinamide N-methyltransferase | D7: P40261 | E7: 0.317 | H7: SwissTargetPrediction | I7: Tier 1 | J7: Meets threshold
A8: Ivermectin | B8: PRKCA | C8: Protein kinase C alpha type | D8: P17252 | E8: 0.431 | H8: SwissTargetPrediction | I8: Tier 1 | J8: Meets threshold
A9: Ivermectin | B9: PRKCD | C9: Protein kinase C delta type | D9: Q05655 | E9: 0.429 | H9: SwissTargetPrediction | I9: Tier 1 | J9: Meets threshold
A10: Ivermectin | B10: PTGS2 | C10: Prostaglandin G/H synthase 2 | D10: P35354 | F10: 0.8 | H10: STITCH | I10: Tier 1 | J10: Meets threshold
A11: Ivermectin | B11: ATP2A2 | C11: Sarcoplasmic/endoplasmic reticulum calcium ATPase 2 | D11: P16615 | E11: 0.273 | H11: SwissTargetPrediction | I11: Tier 2 | J11: Below threshold: STP 0.273 < 0.30
A12: Ivermectin | B12: BRD4 | C12: Bromodomain-containing protein 4 | D12: O60885 | E12: 0.205 | H12: SwissTargetPrediction | I12: Tier 2 | J12: Below threshold: STP 0.205 < 0.30
A13: Ivermectin | B13: CDC25B | C13: M-phase inducer phosphatase 2 | D13: P30305 | E13: 0.222 | H13: SwissTargetPrediction | I13: Tier 2 | J13: Below threshold: STP 0.222 < 0.30
A14: Ivermectin | B14: IDH1 | C14: Isocitrate dehydrogenase [NADP] cytoplasmic | D14: O75874 | E14: 0.247 | H14: SwissTargetPrediction | I14: Tier 2 | J14: Below threshold: STP 0.247 < 0.30
A15: Ivermectin | B15: KEAP1 | C15: Kelch-like ECH-associated protein 1 | D15: Q14145 | E15: 0.273 | H15: SwissTargetPrediction | I15: Tier 2 | J15: Below threshold: STP 0.273 < 0.30
A16: Ivermectin | B16: NR1H4 | C16: Bile acid receptor | D16: Q96RI1 | E16: 0.252 | H16: SwissTargetPrediction | I16: Tier 2 | J16: Below threshold: STP 0.252 < 0.30
A17: Ivermectin | B17: PTPN11 | C17: Tyrosine-protein phosphatase non-receptor type 11 | D17: Q06124 | E17: 0.274 | H17: SwissTargetPrediction | I17: Tier 2 | J17: Below threshold: STP 0.274 < 0.30
A18: Dronedarone | B18: ADRA1A | C18: Alpha-1A adrenergic receptor | D18: P35348 | F18: 0.8 | H18: STITCH | I18: Tier 1 | J18: Meets threshold
A19: Dronedarone | B19: ADRA1D | C19: Alpha-1D adrenergic receptor | D19: P25100 | F19: 0.8 | H19: STITCH | I19: Tier 1 | J19: Meets threshold
A20: Dronedarone | B20: ADRA2B | C20: Alpha-2B adrenergic receptor | D20: P18089 | F20: 0.8 | H20: STITCH | I20: Tier 1 | J20: Meets threshold
A21: Dronedarone | B21: ADRA2C | C21: Alpha-2C adrenergic receptor | D21: P18825 | F21: 0.8 | H21: STITCH | I21: Tier 1 | J21: Meets threshold
A22: Dronedarone | B22: CACNB1 | C22: Voltage-dependent L-type calcium channel subunit beta-1 | D22: Q02641 | F22: 0.8 | H22: STITCH | I22: Tier 1 | J22: Meets threshold
A23: Dronedarone | B23: CACNB4 | C23: Voltage-dependent L-type calcium channel subunit beta-4 | D23: O00305 | F23: 0.8 | H23: STITCH | I23: Tier 1 | J23: Meets threshold
A24: Dronedarone | B24: CYP2D6 | C24: Cytochrome P450 2D6 | D24: P10635 | F24: 0.839 | H24: STITCH | I24: Tier 1 | J24: Meets threshold
A25: Dronedarone | B25: KCNA5 | C25: Potassium voltage-gated channel subfamily A member 5 | D25: P22460 | E25: 1 | F25: 0.849 | H25: STITCH; SwissTargetPrediction | I25: Tier 1 | J25: Meets threshold
A26: Dronedarone | B26: KCNH2 | C26: Potassium voltage-gated channel subfamily H member 2 (hERG) | D26: Q12809 | E26: 1 | F26: 0.886 | H26: STITCH; SwissTargetPrediction | I26: Tier 1 | J26: Meets threshold
A27: Dronedarone | B27: KCNK2 | C27: Potassium channel subfamily K member 2 | D27: O95069 | F27: 0.8 | H27: STITCH | I27: Tier 1 | J27: Meets threshold
A28: Dronedarone | B28: SIRT3 | C28: NAD-dependent protein deacetylase sirtuin-3 | D28: Q9NTG7 | E28: 0.835 | H28: SwissTargetPrediction | I28: Tier 1 | J28: Meets threshold
A29: Dronedarone | B29: ABCB1 | C29: ATP-dependent translocase ABCB1 | D29: P08183 | E29: 0.282 | H29: SwissTargetPrediction | I29: Tier 2 | J29: Below threshold: STP 0.282 < 0.30
A30: Dronedarone | B30: ALK | C30: ALK tyrosine kinase receptor | D30: Q9UM73 | E30: 0.228 | H30: SwissTargetPrediction | I30: Tier 2 | J30: Below threshold: STP 0.228 < 0.30
A31: Dronedarone | B31: CHRM3 | C31: Muscarinic acetylcholine receptor M3 | D31: P20309 | E31: 0.283 | H31: SwissTargetPrediction | I31: Tier 2 | J31: Below threshold: STP 0.283 < 0.30
A32: Dronedarone | B32: DRD2 | C32: D(2) dopamine receptor | D32: P14416 | E32: 0.256 | H32: SwissTargetPrediction | I32: Tier 2 | J32: Below threshold: STP 0.256 < 0.30
A33: Dronedarone | B33: DRD3 | C33: D(3) dopamine receptor | D33: P35462 | E33: 0.256 | H33: SwissTargetPrediction | I33: Tier 2 | J33: Below threshold: STP 0.256 < 0.30
A34: Dronedarone | B34: DRD4 | C34: D(4) dopamine receptor | D34: P21917 | E34: 0.244 | H34: SwissTargetPrediction | I34: Tier 2 | J34: Below threshold: STP 0.244 < 0.30
A35: Dronedarone | B35: HTR2C | C35: 5-hydroxytryptamine receptor 2C | D35: P28335 | E35: 0.238 | H35: SwissTargetPrediction | I35: Tier 2 | J35: Below threshold: STP 0.238 < 0.30
A36: Fenbendazole | B36: ADORA2A | C36: Adenosine receptor A2a | D36: P29274 | E36: 0.955 | H36: SwissTargetPrediction | I36: Tier 1 | J36: Meets threshold
A37: Fenbendazole | B37: CXCL8 | C37: Interleukin-8 (IL-8) | D37: P10145 | F37: 0.7 | H37: STITCH | I37: Tier 1 | J37: Meets threshold
A38: Fenbendazole | B38: MAPK14 | C38: Mitogen-activated protein kinase 14 | D38: Q16539 | E38: 0.989 | H38: SwissTargetPrediction | I38: Tier 1 | J38: Meets threshold
A39: Fenbendazole | B39: TNF | C39: Tumor necrosis factor | D39: P01375 | F39: 0.7 | H39: STITCH | I39: Tier 1 | J39: Meets threshold
A40: Fenbendazole | B40: ABL1 | C40: Tyrosine-protein kinase ABL1 | D40: P00519 | E40: 0.059 | H40: SwissTargetPrediction | I40: Tier 2 | J40: Below threshold: STP 0.059 < 0.30
...
